<mujoco model="G1_URDF_07_24_25_Palm.SLDASM">
  <compiler angle="radian" meshdir="meshes/" />

  <contact>
        <!-- filter the palm from all other finger bodies except the tips -->
        <exclude body1="palm" body2="right_t_link" />
        <exclude body1="palm" body2="right_index_f_link" />
        <exclude body1="palm" body2="right_middle_f_link" />
        <exclude body1="palm" body2="right_ring_f_link" />
        <exclude body1="palm" body2="right_pinky_f_link" />

        <exclude body1="palm" body2="right_thumb_mcp_link" />
        <exclude body1="palm" body2="right_index_proximal_link" />
        <exclude body1="palm" body2="right_middle_proximal_link" />
        <exclude body1="palm" body2="right_ring_proximal_link" />
        <exclude body1="palm" body2="right_pinky_proximal_link" />

        <exclude body1="palm" body2="right_thumb_proximal_link" />
        <exclude body1="palm" body2="right_index_middle_link" />
        <exclude body1="palm" body2="right_middle_middle_link" />
        <exclude body1="palm" body2="right_ring_middle_link" />
        <exclude body1="palm" body2="right_pinky_middle_link" />

        <!-- none of the base fingertip geoms can touch each other -->
        <exclude body1="right_t_link" body2="right_index_f_link" />
        <exclude body1="right_t_link" body2="right_middle_f_link" />
        <exclude body1="right_t_link" body2="right_ring_f_link" />
        <exclude body1="right_t_link" body2="right_pinky_f_link" />

        <exclude body1="right_index_f_link" body2="right_middle_f_link" />
        <exclude body1="right_index_f_link" body2="right_ring_f_link" />
        <exclude body1="right_index_f_link" body2="right_pinky_f_link" />

        <exclude body1="right_middle_f_link" body2="right_ring_f_link" />
        <exclude body1="right_middle_f_link" body2="right_pinky_f_link" />

        <exclude body1="right_ring_f_link" body2="right_pinky_f_link" />

    </contact>

  <default>
        <default class="right_hand">
            <mesh scale="0.001 0.001 0.001" />
            <geom solref="0.02 1.5" solimp="0.9 0.99 0.001"/>
            <joint axis="1 0 0" damping="0.05" armature="0.0002" frictionloss="0.01" />
            <position forcerange="-1 1" />
            <default class="visual">
              <geom group="2" type="mesh" contype="0" conaffinity="0" density="0" material="black"/>
            </default>
            <default class="tip">
              <!-- <geom type="capsule" size="0.012 0.008" pos="0 -0.03 0.015" quat="1 1 0 0" friction="0.7 0.05 0.0002"/> -->
              <geom size="0.01 0.012 0.016" pos="-0.0012969 -0.0335524 0.0145207" quat="0.703552 0.709596 -0.0292107 -0.0252203" type="box" friction="0.7 0.05 0.0002" rgba=".5 .5 .5 .3"/>
            </default>
            <default class="thumb_tip">
              <!-- <geom type="capsule" size="0.012 0.008" pos="0.0 -0.04 -0.015" quat="1 1 0 0" friction="0.7 0.05 0.0002"/> -->
              <geom size="0.01 0.012 0.016" pos="-0.00127744 -0.0455619 -0.0144774" quat="0.708101 0.705072 -0.0294902 -0.024426" type="box" friction="0.7 0.05 0.0002" rgba=".5 .5 .5 .3"/>
            </default>
            <default class="wrist">
                <joint damping="0.5" />
                <default class="wrist_y">
                    <joint axis="0 -1 0" range="-0.523599 0.174533" />
                    <position ctrlrange="-0.523599 0.174533" />
                </default>
                <default class="wrist_x">
                    <joint range="-0.698132 0.488692" />
                    <position ctrlrange="-0.698132 0.488692" />
                </default>
            </default>

            <default class="thumb">
                <default class="thbase">
                    <joint axis="0 0 1" range="-1.0472 1.0472" />
                    <position ctrlrange="-1.1 1.1" />
                </default>
                <default class="thproximal">
                    <joint axis="-1 0 0" range="0 1.7453" />
                    <position ctrlrange="-0.1 1.75" />
                </default>
                <default class="thhub">
                    <joint axis="-1 0 0" range="0 1.4" />
                    <position ctrlrange="-0.1 1.5" />
                </default>
                <default class="thmiddle">
                    <joint axis="0 -1 0" range="0 1.2217" armature="0.00014375"/>
                    <position ctrlrange="-0.1 1.3" />
                </default>
                <default class="thdistal">
                    <joint range="0 1.5708" armature="0.00014375"/>
                    <position ctrlrange="-0.1 1.58" />
                    <geom friction="0.7 0.05 0.0002" />
                </default>
            </default>

            <default class="metacarpal">
                <joint axis="0.573576 0 0.819152" range="0 1.5708" armature="0.000002306"/>
                <position ctrlrange="-0.1 1.58" />
            </default>
            <default class="knuckle">
                <joint axis="0 -1 0" range="-0.2618 0.2618" armature="0.000002306"/>
                <position ctrlrange="-0.27 0.27" />
            </default>
            <default class="proximal">
                <joint range="0 1.5708" armature="0.00014375"/>
                <position ctrlrange="-0.1 1.58" />
            </default>
            <default class="middle_distal">
                <joint range="0 1.5708" armature="0.00014375"/>
                <position ctrlrange="-0.1 1.58" />
                <geom friction="0.7 0.05 0.0002" />
            </default>

            <default class="plastic">
                <geom friction="0.7 0.05 0.0002" />
                <default class="plastic_visual">
                    <geom type="mesh" contype="0" conaffinity="0" density="0" group="2" />
                </default>
                <default class="plastic_collision">
                    <geom group="3" />
                </default>
            </default>
        </default>
  </default>

  <asset>
    <material name="black" rgba="0.2 0.2 0.2 1"/>
    <material name="gray" rgba="0.5 0.5 0.5 1"/>
    <mesh name="tetheria_mount" file="tetheria_mount.obj"/>

    <mesh name="right_frame_link" content_type="model/stl" file="right_frame_link.STL"/>
    <mesh name="right_pinky_prismatic_2_link" content_type="model/stl" file="right_pinky_prismatic_2_link.STL"/>
    <mesh name="right_index_prismatic_1_link" content_type="model/stl" file="right_index_prismatic_1_link.STL"/>
    <mesh name="right_middle_prismatic_1_link" content_type="model/stl" file="right_middle_prismatic_1_link.STL"/>
    <mesh name="right_middle_prismatic_2_link" content_type="model/stl" file="right_middle_prismatic_2_link.STL"/>
    <mesh name="right_ring_prismatic_2_link" content_type="model/stl" file="right_ring_prismatic_2_link.STL"/>
    <mesh name="right_pinky_prismatic_1_link" content_type="model/stl" file="right_pinky_prismatic_1_link.STL"/>
    <mesh name="right_ring_prismatic_1_link" content_type="model/stl" file="right_ring_prismatic_1_link.STL"/>
    <mesh name="right_pinky_f_link" content_type="model/stl" file="right_pinky_f_link.STL"/>
    <mesh name="right_pinky_proximal_link" content_type="model/stl" file="right_pinky_proximal_link.STL"/>
    <mesh name="right_pinky_middle_link" content_type="model/stl" file="right_pinky_middle_link.STL"/>
    <mesh name="right_pinky_distal_link" content_type="model/stl" file="right_pinky_distal_link.STL"/>
    <mesh name="right_pinky_tip_link" content_type="model/stl" file="right_pinky_tip_link.STL"/>
    <mesh name="right_middle_f_link" content_type="model/stl" file="right_middle_f_link.STL"/>
    <mesh name="right_middle_proximal_link" content_type="model/stl" file="right_middle_proximal_link.STL"/>
    <mesh name="right_middle_middle_link" content_type="model/stl" file="right_middle_middle_link.STL"/>
    <mesh name="right_middle_distal_link" content_type="model/stl" file="right_middle_distal_link.STL"/>
    <mesh name="right_middle_tip_link" content_type="model/stl" file="right_middle_tip_link.STL"/>
    <mesh name="right_index_f_link" content_type="model/stl" file="right_index_f_link.STL"/>
    <mesh name="right_index_proximal_link" content_type="model/stl" file="right_index_proximal_link.STL"/>
    <mesh name="right_index_middle_link" content_type="model/stl" file="right_index_middle_link.STL"/>
    <mesh name="right_index_distal_link" content_type="model/stl" file="right_index_distal_link.STL"/>
    <mesh name="right_index_tip_link" content_type="model/stl" file="right_index_tip_link.STL"/>
    <mesh name="right_ring_f_link" content_type="model/stl" file="right_ring_f_link.STL"/>
    <mesh name="right_ring_proximal_link" content_type="model/stl" file="right_ring_proximal_link.STL"/>
    <mesh name="right_ring_middle_link" content_type="model/stl" file="right_ring_middle_link.STL"/>
    <mesh name="right_ring_distal_link" content_type="model/stl" file="right_ring_distal_link.STL"/>
    <mesh name="right_ring_tip_link" content_type="model/stl" file="right_ring_tip_link.STL"/>
    <mesh name="right_index_prismatic_2_link" content_type="model/stl" file="right_index_prismatic_2_link.STL"/>
    <mesh name="right_t_link" content_type="model/stl" file="right_t_link.STL"/>
    <mesh name="right_thumb_mcp_link" content_type="model/stl" file="right_thumb_mcp_link.STL"/>
    <mesh name="right_thumb_proximal_link" content_type="model/stl" file="right_thumb_proximal_link.STL"/>
    <mesh name="right_thumb_distal_link" content_type="model/stl" file="right_thumb_distal_link.STL"/>
    <mesh name="right_thumb_tip_link" content_type="model/stl" file="right_thumb_tip_link.STL"/>
    <mesh name="right_palm_cover_link" content_type="model/stl" file="right_palm_cover_link.STL"/>
  </asset>

  <worldbody>

    <!-- <body name="mocap" mocap="true" pos="0 0 0" quat="1 0 0 0">
            <geom type="box" group="1" size="0.02 0.02 0.02" contype="0" conaffinity="0"
                rgba=".9 .5 .5 1" />
    </body> -->

    <body name="tetheria_mount" pos="0 0 0" quat="1 0 0 0">
      <geom name="tetheria_mount_visual" pos="0 0 0" quat="1 0 0 0" class="visual" mesh="tetheria_mount"/>
      <site name="grasp_site" pos="0.11 0.0 0.03" group="4"/>
      <body name="palm" pos="0.03 0.0105 -0.015" quat="-0.4056 0.5792 -0.5792 0.4056">
        <geom type="mesh" rgba="0.611765 0.658824 0.670588 1" mesh="right_palm_cover_link" class="plastic_collision"/>
        <geom type="mesh" rgba="0.611765 0.658824 0.670588 1" mesh="right_frame_link"/>
      <!-- <body name="right_pinky_prismatic_2_link" pos="-0.040926 -0.010306 0.079736" quat="0.998019 0.00182998 -0.0523041 0.034918">
        <inertial pos="1.7821e-11 -0.000789769 -0.00253442" quat="0.838296 0.545215 0 0" mass="0.000142104" diaginertia="1.57248e-09 1.36648e-09 6.62328e-10"/>
        <joint name="right_pinky_prismatic_2" pos="0 0 0" axis="0 0 -1" type="slide" range="0 0.0178"/>
        <geom type="mesh" rgba="0.611765 0.658824 0.670588 1" mesh="right_pinky_prismatic_2_link"/>
      </body>
      <body name="right_index_prismatic_1_link" pos="0.03597 -0.007732 0.092978" quat="0.999505 0.000456857 0.026173 -0.0174466">
        <inertial pos="-1.52915e-11 -0.000789769 -0.00253442" quat="0.838296 0.545215 0 0" mass="0.000142104" diaginertia="1.57248e-09 1.36648e-09 6.62328e-10"/>
        <joint name="right_index_prismatic_1" pos="0 0 0" axis="0 0 -1" type="slide" range="0 0.0178"/>
        <geom type="mesh" rgba="0.611765 0.658824 0.670588 1" mesh="right_index_prismatic_1_link"/>
      </body>
      <body name="right_middle_prismatic_1_link" pos="0.013506 -0.0064 0.093809">
        <inertial pos="0 -0.000789769 -0.00253442" quat="0.838296 0.545215 0 0" mass="0.000142104" diaginertia="1.57248e-09 1.36648e-09 6.62328e-10"/>
        <joint name="right_middle_prismatic_1" pos="0 0 0" axis="0 0 -1" type="slide" range="0 0.0178"/>
        <geom type="mesh" rgba="0.611765 0.658824 0.670588 1" mesh="right_middle_prismatic_1_link"/>
      </body>
      <body name="right_middle_prismatic_2_link" pos="0.0035001 -0.0064 0.093809">
        <inertial pos="0 -0.000789769 -0.00253442" quat="0.838296 0.545215 0 0" mass="0.000142104" diaginertia="1.57248e-09 1.36648e-09 6.62328e-10"/>
        <joint name="right_middle_prismatic_2" pos="0 0 0" axis="0 0 -1" type="slide" range="0 0.0178"/>
        <geom type="mesh" rgba="0.611765 0.658824 0.670588 1" mesh="right_middle_prismatic_2_link"/>
      </body>
      <body name="right_ring_prismatic_2_link" pos="-0.018964 -0.0077317 0.092979" quat="0.999505 0.000456857 -0.026173 0.0174466">
        <inertial pos="-2.34683e-12 -0.000789769 -0.00253442" quat="0.838296 0.545215 0 0" mass="0.000142104" diaginertia="1.57248e-09 1.36648e-09 6.62328e-10"/>
        <joint name="right_ring_prismatic_2" pos="0 0 0" axis="0 0 -1" type="slide" range="0 0.0178"/>
        <geom type="mesh" rgba="0.611765 0.658824 0.670588 1" mesh="right_ring_prismatic_2_link"/>
      </body>
      <body name="right_pinky_prismatic_1_link" pos="-0.030999 -0.0096108 0.080782" quat="0.998019 0.00182998 -0.0523041 0.034918">
        <inertial pos="-2.62201e-12 -0.000789769 -0.00253442" quat="0.838296 0.545215 0 0" mass="0.000142104" diaginertia="1.57248e-09 1.36648e-09 6.62328e-10"/>
        <joint name="right_pinky_prismatic_1" pos="0 0 0" axis="0 0 -1" type="slide" range="0 0.0178"/>
        <geom type="mesh" rgba="0.611765 0.658824 0.670588 1" mesh="right_pinky_prismatic_1_link"/>
      </body>
      <body name="right_ring_prismatic_1_link" pos="-0.0089773 -0.007383 0.093502" quat="0.999505 0.000456857 -0.026173 0.0174466">
        <inertial pos="-1.76677e-11 -0.000789769 -0.00253442" quat="0.838296 0.545215 0 0" mass="0.000142104" diaginertia="1.57248e-09 1.36648e-09 6.62328e-10"/>
        <joint name="right_ring_prismatic_1" pos="0 0 0" axis="0 0 -1" type="slide" range="0 0.0178"/>
        <geom type="mesh" rgba="0.611765 0.658824 0.670588 1" mesh="right_ring_prismatic_1_link"/>
      </body> -->
      <body name="right_pinky_f_link" pos="-0.036912 -0.0066167 0.087021" quat="0.998019 0.00182998 -0.0523041 0.034918">
        <inertial pos="0 0 0.0017" mass="0.000169697" diaginertia="1.29009e-09 1.29009e-09 7.6801e-10"/>
        <joint name="right_pinky_mcp_abd" pos="0 0 0" axis="0 1 0" range="-0.3491 0.3491" class= "knuckle"/>
        <geom type="mesh" rgba="0.611765 0.658824 0.670588 1" mesh="right_pinky_f_link" class="plastic_collision"/>
        <body name="right_pinky_proximal_link" pos="0 0 0.0034">
          <inertial pos="-4.24866e-08 -0.00357857 0.0205176" quat="0.706879 0.0179383 -0.0179383 0.706879" mass="0.00600337" diaginertia="8.89987e-07 8.65277e-07 2.05351e-07"/>
          <joint name="right_pinky_mcp_flex" pos="0 0 0" axis="1 0 0" range="0 1.5708" class="metacarpal"/>
          <geom type="mesh" rgba="1 0.4 0.4 1" mesh="right_pinky_proximal_link" class="plastic_collision"/>
          <body name="right_pinky_middle_link" pos="0 -0.0014554 0.043" quat="0.999962 0.00872639 0 0">
            <inertial pos="1.1729e-08 -0.00110519 0.0093962" quat="0.706846 -0.0191898 0.019202 0.706846" mass="0.00237591" diaginertia="1.6252e-07 1.35575e-07 7.42876e-08"/>
            <joint name="right_pinky_pip" pos="0 0 0" axis="1 0 0" range="0 1.5708" class="proximal"/>
            <geom type="mesh" rgba="0.490196 0.490196 0.490196 1" mesh="right_pinky_middle_link" class="plastic_collision"/>
            <body name="right_pinky_distal_link" pos="0 0.00036966 0.021997" quat="1 0.00052935 0 0">
              <inertial pos="-0.00184407 0.000358264 0.0107282" quat="0.696242 -0.184421 0.0500633 0.691903" mass="0.00309314" diaginertia="1.89076e-07 1.75557e-07 6.3941e-08"/>
              <joint name="right_pinky_dip" pos="0 0 0" axis="1 0 0" range="0 1.5708" class="middle_distal"/>
              <geom type="mesh" rgba="0 1 1 1" mesh="right_pinky_distal_link" class="plastic_collision"/>
              <geom pos="0 0.0033789 0.024944" quat="0.999999 -0.0015829 0 0" type="mesh" rgba="1 0.227451 0.882353 1" mesh="right_pinky_tip_link" class="plastic_collision"/>
              <site name="pf_tip" pos="0 -0.003 0.023" group="4"/>
            </body>
          </body>
        </body>
      </body>
      <body name="right_middle_f_link" pos="0.0085 -0.003 0.10061">
        <inertial pos="0 0 0.0017" mass="0.000169697" diaginertia="1.29009e-09 1.29009e-09 7.6801e-10"/>
        <joint name="right_middle_mcp_abd" pos="0 0 0" axis="0 1 0" range="-0.3491 0.3491" class="knuckle" />
        <geom type="mesh" rgba="0.611765 0.658824 0.670588 1" mesh="right_middle_f_link" class="plastic_collision"/>
        <body name="right_middle_proximal_link" pos="0 0 0.0034">
          <inertial pos="-5.79907e-08 -0.00357858 0.0205176" quat="0.706861 0.0179374 -0.0179384 0.706897" mass="0.00600338" diaginertia="8.89988e-07 8.65279e-07 2.05352e-07"/>
          <joint name="right_middle_mcp_flex" pos="0 0 0" axis="1 0 0" range="0 1.5708" class="metacarpal" />
          <geom type="mesh" rgba="1 0.4 0.4 1" mesh="right_middle_proximal_link" class="plastic_collision"/>
          <body name="right_middle_middle_link" pos="0 -0.0014554 0.043" quat="0.999962 0.00872639 0 0">
            <inertial pos="9.42153e-09 -0.00110516 0.00939618" quat="0.706832 -0.0191899 0.0192034 0.706861" mass="0.0023759" diaginertia="1.62521e-07 1.35575e-07 7.42872e-08"/>
            <joint name="right_middle_pip" pos="0 0 0" axis="1 0 0" range="0 1.5708" class="proximal" />
            <geom type="mesh" rgba="0.490196 0.490196 0.490196 1" mesh="right_middle_middle_link" class="plastic_collision"/>
            <body name="right_middle_distal_link" pos="0 0.00036966 0.021997" quat="1 0.00052935 0 0">
              <inertial pos="-0.00184407 0.000358307 0.0107282" quat="0.696243 -0.184422 0.0500631 0.691902" mass="0.00309312" diaginertia="1.89075e-07 1.75556e-07 6.39407e-08"/>
              <joint name="right_middle_dip" pos="0 0 0" axis="1 0 0" range="0 1.5708" class="middle_distal" />
              <geom type="mesh" rgba="0 1 1 1" mesh="right_middle_distal_link" class="plastic_collision"/>
              <geom pos="0 0.0033789 0.024944" quat="0.999999 -0.0015829 0 0" type="mesh" rgba="1 0.227451 0.882353 1" mesh="right_middle_tip_link" class="plastic_collision"/>
              <site name="mf_tip" pos="0 -0.003 0.023" group="4"/>
            </body>
          </body>
        </body>
      </body>
      <body name="right_index_f_link" pos="0.031448 -0.004172 0.10003" quat="0.999505 0.000456857 0.026173 -0.0174466">
        <inertial pos="0 0 0.0017" mass="0.000169697" diaginertia="1.29009e-09 1.29009e-09 7.6801e-10"/>
        <joint name="right_index_mcp_abd" pos="0 0 0" axis="0 1 0" range="-0.3491 0.3491" class="knuckle" />
        <geom type="mesh" rgba="0.611765 0.658824 0.670588 1" mesh="right_index_f_link" class="plastic_collision"/>
        <body name="right_index_proximal_link" pos="0 0 0.0034">
          <inertial pos="-6.14568e-08 -0.00357858 0.0205176" quat="0.706858 0.0179374 -0.0179385 0.7069" mass="0.00600337" diaginertia="8.89988e-07 8.65278e-07 2.05352e-07"/>
          <joint name="right_index_mcp_flex" pos="0 0 0" axis="1 0 0" range="0 1.5708" class="metacarpal" />
          <geom type="mesh" rgba="1 0.4 0.4 1" mesh="right_index_proximal_link" class="plastic_collision"/>
          <body name="right_index_middle_link" pos="0 -0.0014554 0.043" quat="0.999962 0.00872639 0 0">
            <inertial pos="2.38785e-08 -0.00110516 0.00939619" quat="0.706833 -0.0191908 0.0192032 0.70686" mass="0.0023759" diaginertia="1.62521e-07 1.35575e-07 7.42871e-08"/>
            <joint name="right_index_pip" pos="0 0 0" axis="1 0 0" range="0 1.5708" class="proximal" />
            <geom type="mesh" rgba="0.490196 0.490196 0.490196 1" mesh="right_index_middle_link" class="plastic_collision"/>
            <body name="right_index_distal_link" pos="0 0.00036966 0.021997" quat="1 0.00052935 0 0">
              <inertial pos="-0.00184412 0.000358323 0.0107277" quat="0.696253 -0.184428 0.0500635 0.69189" mass="0.00309312" diaginertia="1.89064e-07 1.75544e-07 6.39413e-08"/>
              <joint name="right_index_dip" pos="0 0 0" axis="1 0 0" range="0 1.5708" class="middle_distal" />
              <geom type="mesh" rgba="0 1 1 1" mesh="right_index_distal_link" class="plastic_collision"/>
              <geom pos="0 0.0033789 0.024944" quat="0.999999 -0.0015829 0 0" type="mesh" rgba="1 0.227451 0.882353 1" mesh="right_index_tip_link" class="plastic_collision"/>
              <site name="if_tip" pos="0 -0.003 0.023" group="4"/>
            </body>
          </body>
        </body>
      </body>
      <body name="right_ring_f_link" pos="-0.014448 -0.004172 0.10003" quat="0.999505 0.000456857 -0.026173 0.0174466">
        <inertial pos="0 0 0.0017" mass="0.000169697" diaginertia="1.29009e-09 1.29009e-09 7.6801e-10"/>
        <joint name="right_ring_mcp_abd" pos="0 0 0" axis="0 1 0" range="-0.3491 0.3491" class="knuckle"/>
        <geom type="mesh" rgba="0.611765 0.658824 0.670588 1" mesh="right_ring_f_link" class="plastic_collision"/>
        <body name="right_ring_proximal_link" pos="0 0 0.0034">
          <inertial pos="-4.27735e-08 -0.00357857 0.0205176" quat="0.706879 0.0179383 -0.0179383 0.706879" mass="0.00600337" diaginertia="8.89987e-07 8.65277e-07 2.05351e-07"/>
          <joint name="right_ring_mcp_flex" pos="0 0 0" axis="1 0 0" range="0 1.5708" class="metacarpal"/>
          <geom type="mesh" rgba="1 0.4 0.4 1" mesh="right_ring_proximal_link" class="plastic_collision"/>
          <body name="right_ring_middle_link" pos="0 -0.0014554 0.043" quat="0.999962 0.00872639 0 0">
            <inertial pos="5.2917e-09 -0.00110519 0.0093962" quat="0.706846 -0.0191893 0.019202 0.706846" mass="0.00237591" diaginertia="1.62521e-07 1.35575e-07 7.42877e-08"/>
            <joint name="right_ring_pip" pos="0 0 0" axis="1 0 0" range="0 1.5708" class="proximal" />
            <geom type="mesh" rgba="0.490196 0.490196 0.490196 1" mesh="right_ring_middle_link" class="plastic_collision"/>
            <body name="right_ring_distal_link" pos="0 0.00036966 0.021997" quat="1 0.00052935 0 0">
              <inertial pos="-0.00184407 0.000358289 0.0107282" quat="0.696244 -0.184422 0.050064 0.691901" mass="0.00309314" diaginertia="1.89076e-07 1.75558e-07 6.39409e-08"/>
              <joint name="right_ring_dip" pos="0 0 0" axis="1 0 0" range="0 1.5708" class="middle_distal"/>
              <geom type="mesh" rgba="0 1 1 1" mesh="right_ring_distal_link" class="plastic_collision"/>
              <geom pos="0 0.0033789 0.024944" quat="0.999999 -0.0015829 0 0" type="mesh" rgba="1 0.227451 0.882353 1" mesh="right_ring_tip_link" class="plastic_collision"/>
              <site name="rf_tip" pos="0 -0.003 0.023" group="4"/>
            </body>
          </body>
        </body>
      </body>
      <!-- <body name="right_index_prismatic_2_link" pos="0.025984 -0.0073832 0.093502" quat="0.999505 0.000456857 0.026173 -0.0174466">
        <inertial pos="-1.52915e-11 -0.000789769 -0.00253442" quat="0.838296 0.545215 0 0" mass="0.000142104" diaginertia="1.57248e-09 1.36648e-09 6.62328e-10"/>
        <joint name="right_index_prismatic_2" pos="0 0 0" axis="0 0 -1" type="slide" range="0 0.0178"/>
        <geom type="mesh" rgba="0.611765 0.658824 0.670588 1" mesh="right_index_prismatic_2_link"/>
      </body> -->
      <body name="right_t_link" pos="0.026317 -0.0175 0.02956" quat="0.579233 -0.40557 0.405572 -0.579235">
        <inertial pos="-0.000792597 0.00920489 0.00837042" quat="0.968785 -0.231969 -0.0564922 0.066746" mass="0.00893482" diaginertia="1.11708e-06 8.42419e-07 4.36164e-07"/>
        <joint name="right_thumb_cmc_abd" pos="0 0 0" axis="0 1 0" range="0 1.7453" class="thproximal"/>
        <geom type="mesh" rgba="0 0 1 1" mesh="right_t_link" class="plastic_collision"/>
        <body name="right_thumb_mcp_link" pos="-0.0024625 0.011988 0.019805" quat="0.988119 0.0527639 -0.058289 0.132056">
          <inertial pos="-3.98621e-09 -0.0014303 0.0147562" quat="0.706814 0.0205256 -0.020536 0.706804" mass="0.0102694" diaginertia="1.58158e-06 1.39018e-06 6.7267e-07"/>
          <joint name="right_thumb_cmc_flex" pos="0 0 0" axis="1 0 0" range="0 0.9559" class="thhub"/>
          <geom type="mesh" rgba="1 0.4 0.4 1" mesh="right_thumb_mcp_link" class="plastic_collision"/>
          <body name="right_thumb_proximal_link" pos="0 0.0013652 0.035982">
            <inertial pos="-9.60413e-08 -0.00147723 0.0133935" quat="0.707028 -0.010773 0.0107885 0.707021" mass="0.00574573" diaginertia="6.77924e-07 5.00351e-07 3.51862e-07"/>
            <joint name="right_thumb_mcp" pos="0 0 0" axis="1 0 0" range="0 1.5708" class="thmiddle"/>
            <geom type="mesh" rgba="0 0.6 1 1" mesh="right_thumb_proximal_link" class="plastic_collision"/>
            <body name="right_thumb_distal_link" pos="0 0.00052357 0.029995">
              <inertial pos="-0.00113926 -0.00130909 0.0133464" quat="0.698666 -0.140008 0.0513212 0.699736" mass="0.00692863" diaginertia="6.65186e-07 5.66522e-07 2.78338e-07"/>
              <joint name="right_thumb_ip" pos="0 0 0" axis="1 0 0" range="0 1.5708" class="thdistal"/>
              <geom type="mesh" rgba="0.792157 0.819608 0.933333 1" mesh="right_thumb_distal_link" class="plastic_collision"/>
              <geom pos="0 0.0024685 0.029987" quat="0.999982 0.00592597 0 0" type="mesh" rgba="1 0 1 1" mesh="right_thumb_tip_link" class="plastic_collision"/>
              <site name="th_tip" pos="0 -0.005 0.027" group="4"/>
            </body>
          </body>
        </body>
      </body>
      </body>
    </body>
  </worldbody>

    <actuator>

        <!-- <position name="rh_A_TBJ0" tendon="rh_TBJ0" class="thdistal" /> -->

        <position name="right_thumb_A_pip" joint="right_thumb_ip" class="thdistal" />
        <position name="right_thumb_A_mcp_abd" joint="right_thumb_cmc_abd" class="thproximal" />
        <position name="right_thumb_A_cmc_flex" joint="right_thumb_cmc_flex" class="thhub" />

        <!-- <position name="rh_A_FFJ0" tendon="rh_FFJ0" class="middle_distal" /> -->
        <position name="right_index_A_pip" joint="right_index_pip" class="middle_distal" />
        <position name="right_index_A_mcp_abd" joint="right_index_mcp_abd" class="knuckle" />
        <position name="right_index_A_mcp_flex" joint="right_index_mcp_flex" class="metacarpal" />

        <position name="right_middle_A_pip" joint="right_middle_pip" class="middle_distal" />
        <position name="right_middle_A_mcp_abd" joint="right_middle_mcp_abd" class="knuckle" />
        <position name="right_middle_A_mcp_flex" joint="right_middle_mcp_flex" class="metacarpal" />

        <position name="right_ring_A_pip" joint="right_ring_pip" class="middle_distal" />
        <position name="right_ring_A_mcp_abd" joint="right_ring_mcp_abd" class="knuckle" />
        <position name="right_ring_A_mcp_flex" joint="right_ring_mcp_flex" class="metacarpal" />

        <position name="right_pinky_A_pip" joint="right_pinky_pip" class="middle_distal" />
        <position name="right_pinky_A_mcp_abd" joint="right_pinky_mcp_abd" class="knuckle" />
        <position name="right_pinky_A_mcp_flex" joint="right_pinky_mcp_flex" class="metacarpal" />
    </actuator>

    <equality>
        <!-- <weld body1="mocap" body2="tetheria_mount" solref="0.01 1" solimp=".9 .9 0.01" /> -->
        <joint joint1="right_thumb_mcp" joint2="right_thumb_ip"/>
        <joint joint1="right_index_pip" joint2="right_index_dip"/>
        <joint joint1="right_middle_pip" joint2="right_middle_dip"/>
        <joint joint1="right_ring_pip" joint2="right_ring_dip"/>
        <joint joint1="right_pinky_pip" joint2="right_pinky_dip"/>
    </equality>

</mujoco>
